Error Type : HttpForbiddenError
Error Message : HttpError accessing <https://dataflow.googleapis.com/v1b3/projects/stellar-acre-374223/locations/us-central1/jobs?alt=json>: response: <{'vary': 'Origin, X-Origin, Referer', 'content-type': 'application/json; charset=UTF-8', 'date': 'Thu, 12 Jan 2023 17:58:50 GMT', 'server': 'ESF', 'cache-control': 'private', 'x-xss-protection': '0', 'x-frame-options': 'SAMEORIGIN', 'x-content-type-options': 'nosniff', 'transfer-encoding': 'chunked', 'status': '403', 'content-length': '1033', '-content-encoding': 'gzip'}>, content <{
  "error": {
    "code": 403,
    "message": "Dataflow API has not been used in project 504444247109 before or it is disabled. Enable it by visiting https://console.developers.google.com/apis/api/dataflow.googleapis.com/overview?project=504444247109 then retry. If you enabled this API recently, wait a few minutes for the action to propagate to our systems and retry.",
    "status": "PERMISSION_DENIED",
    "details": [
      {
        "@type": "type.googleapis.com/google.rpc.Help",
        "links": [
          {
            "description": "Google developers console API activation",
            "url": "https://console.developers.google.com/apis/api/dataflow.googleapis.com/overview?project=504444247109"
          }
        ]
      },
      {
        "@type": "type.googleapis.com/google.rpc.ErrorInfo",
        "reason": "SERVICE_DISABLED",
        "domain": "googleapis.com",
        "metadata": {
          "consumer": "projects/504444247109",
          "service": "dataflow.googleapis.com"
        }
      }
    ]
  }
}
>
  File "/main.py", line 33, in <module>
    preprocessing.data_sampler_run(sys.argv)

  File "/vertexevaluation/lib/preprocessing.py", line 431, in data_sampler_run
    result = extend_sampler_pipeline(

  File "/usr/local/lib/python3.8/site-packages/apache_beam/pipeline.py", line 546, in run
    return Pipeline.from_runner_api(

  File "/usr/local/lib/python3.8/site-packages/apache_beam/pipeline.py", line 573, in run
    return self.runner.run_pipeline(self, self._options)

  File "/usr/local/lib/python3.8/site-packages/apache_beam/runners/dataflow/dataflow_runner.py", line 582, in run_pipeline
    self.dataflow_client.create_job(self.job), self)

  File "/usr/local/lib/python3.8/site-packages/apache_beam/utils/retry.py", line 253, in wrapper
    return fun(*args, **kwargs)

  File "/usr/local/lib/python3.8/site-packages/apache_beam/runners/dataflow/internal/apiclient.py", line 766, in create_job
    return self.submit_job_description(job)

  File "/usr/local/lib/python3.8/site-packages/apache_beam/utils/retry.py", line 253, in wrapper
    return fun(*args, **kwargs)

  File "/usr/local/lib/python3.8/site-packages/apache_beam/runners/dataflow/internal/apiclient.py", line 867, in submit_job_description
    response = self._client.projects_locations_jobs.Create(request)

  File "/usr/local/lib/python3.8/site-packages/apache_beam/runners/dataflow/internal/clients/dataflow/dataflow_v1b3_client.py", line 701, in Create
    return self._RunMethod(

  File "/usr/local/lib/python3.8/site-packages/apitools/base/py/base_api.py", line 731, in _RunMethod
    return self.ProcessHttpResponse(method_config, http_response, request)

  File "/usr/local/lib/python3.8/site-packages/apitools/base/py/base_api.py", line 737, in ProcessHttpResponse
    self.__ProcessHttpResponse(method_config, http_response, request))

  File "/usr/local/lib/python3.8/site-packages/apitools/base/py/base_api.py", line 603, in __ProcessHttpResponse
    raise exceptions.HttpError.FromResponse(

